Workbook

Sheet Summary
A3: category | B3: Count of ticket_id | C3: Average of resolution_hours
A4: Billing | B4: 8 | C4: 37.666667
A5: Email Delivery | B5: 6 | C5: 20.5
A6: Integration Sync | B6: 8 | C6: 39.5
A7: Login | B7: 9 | C7: 4.2857143
A8: Scheduling | B8: 7 | C8: 45.2
A9: SMS Delivery | B9: 8 | C9: 16
A10: Grand Total | B10: 46 | C10: 27.387097

Sheet Tickets
A1: ticket_id | B1: client_id | C1: category | D1: priority | E1: status | F1: created_at | G1: resolved_at | H1: resolution_hours | I1: client_name | J1: plan_tier
A2: 1001 | B2: 6 | C2: SMS Delivery | D2: High | E2: Solved | F2: 46291.603 | G2: 46292.436 | H2: =IF(E2="Solved",ROUND((G2-F2)*24,1),"") -> 20 | I2: =_xlfn.XLOOKUP(B2,Clients!A:A,Clients!B:B,"Not found") -> Redpoint Climbing Center | J2: =_xlfn.XLOOKUP(B2,Clients!A:A,Clients!C:C,"Not found") -> Pro
A3: 1002 | B3: 6 | C3: Integration Sync | D3: Urgent | E3: Solved | F3: 46299.936 | G3: 46300.186 | H3: =IF(E3="Solved",ROUND((G3-F3)*24,1),"") -> 6 | I3: =_xlfn.XLOOKUP(B3,Clients!A:A,Clients!B:B,"Not found") -> Redpoint Climbing Center | J3: =_xlfn.XLOOKUP(B3,Clients!A:A,Clients!C:C,"Not found") -> Pro
A4: 1003 | B4: 6 | C4: Login | D4: Normal | E4: Pending | F4: 46310.353 | G4: NULL | H4: =IF(E4="Solved",ROUND((G4-F4)*24,1),"") | I4: =_xlfn.XLOOKUP(B4,Clients!A:A,Clients!B:B,"Not found") -> Redpoint Climbing Center | J4: =_xlfn.XLOOKUP(B4,Clients!A:A,Clients!C:C,"Not found") -> Pro
A5: 1004 | B5: 6 | C5: Billing | D5: High | E5: Open | F5: 46315.353 | G5: NULL | H5: =IF(E5="Solved",ROUND((G5-F5)*24,1),"") | I5: =_xlfn.XLOOKUP(B5,Clients!A:A,Clients!B:B,"Not found") -> Redpoint Climbing Center | J5: =_xlfn.XLOOKUP(B5,Clients!A:A,Clients!C:C,"Not found") -> Pro
A6: 1005 | B6: 13 | C6: Email Delivery | D6: Normal | E6: Solved | F6: 46295.77 | G6: 46297.02 | H6: =IF(E6="Solved",ROUND((G6-F6)*24,1),"") -> 30 | I6: =_xlfn.XLOOKUP(B6,Clients!A:A,Clients!B:B,"Not found") -> Crux Factory | J6: =_xlfn.XLOOKUP(B6,Clients!A:A,Clients!C:C,"Not found") -> Pro
A7: 1006 | B7: 13 | C7: Integration Sync | D7: High | E7: Open | F7: 46312.603 | G7: NULL | H7: =IF(E7="Solved",ROUND((G7-F7)*24,1),"") | I7: =_xlfn.XLOOKUP(B7,Clients!A:A,Clients!B:B,"Not found") -> Crux Factory | J7: =_xlfn.XLOOKUP(B7,Clients!A:A,Clients!C:C,"Not found") -> Pro
A8: 1007 | B8: 13 | C8: SMS Delivery | D8: Urgent | E8: Open | F8: 46315.77 | G8: NULL | H8: =IF(E8="Solved",ROUND((G8-F8)*24,1),"") | I8: =_xlfn.XLOOKUP(B8,Clients!A:A,Clients!B:B,"Not found") -> Crux Factory | J8: =_xlfn.XLOOKUP(B8,Clients!A:A,Clients!C:C,"Not found") -> Pro
A9: 1008 | B9: 1 | C9: SMS Delivery | D9: High | E9: Open | F9: 46314.603 | G9: NULL | H9: =IF(E9="Solved",ROUND((G9-F9)*24,1),"") | I9: =_xlfn.XLOOKUP(B9,Clients!A:A,Clients!B:B,"Not found") -> Summit Bouldering | J9: =_xlfn.XLOOKUP(B9,Clients!A:A,Clients!C:C,"Not found") -> Pro
A10: 1009 | B10: 1 | C10: Scheduling | D10: Low | E10: Solved | F10: 46254.103 | G10: 46256.186 | H10: =IF(E10="Solved",ROUND((G10-F10)*24,1),"") -> 50 | I10: =_xlfn.XLOOKUP(B10,Clients!A:A,Clients!B:B,"Not found") -> Summit Bouldering | J10: =_xlfn.XLOOKUP(B10,Clients!A:A,Clients!C:C,"Not found") -> Pro
A11: 1010 | B11: 2 | C11: Login | D11: Normal | E11: Solved | F11: 46233.27 | G11: 46233.436 | H11: =IF(E11="Solved",ROUND((G11-F11)*24,1),"") -> 4 | I11: =_xlfn.XLOOKUP(B11,Clients!A:A,Clients!B:B,"Not found") -> Granite Hall Climbing | J11: =_xlfn.XLOOKUP(B11,Clients!A:A,Clients!C:C,"Not found") -> Growth
A12: 1011 | B12: 2 | C12: Billing | D12: Low | E12: Solved | F12: 46304.103 | G12: 46307.103 | H12: =IF(E12="Solved",ROUND((G12-F12)*24,1),"") -> 72 | I12: =_xlfn.XLOOKUP(B12,Clients!A:A,Clients!B:B,"Not found") -> Granite Hall Climbing | J12: =_xlfn.XLOOKUP(B12,Clients!A:A,Clients!C:C,"Not found") -> Growth
A13: 1012 | B13: 4 | C13: Integration Sync | D13: High | E13: Solved | F13: 46212.436 | G13: 46213.686 | H13: =IF(E13="Solved",ROUND((G13-F13)*24,1),"") -> 30 | I13: =_xlfn.XLOOKUP(B13,Clients!A:A,Clients!B:B,"Not found") -> Overhang Collective | J13: =_xlfn.XLOOKUP(B13,Clients!A:A,Clients!C:C,"Not found") -> Pro
A14: 1013 | B14: 4 | C14: Email Delivery | D14: Normal | E14: Solved | F14: 46266.603 | G14: 46267.353 | H14: =IF(E14="Solved",ROUND((G14-F14)*24,1),"") -> 18 | I14: =_xlfn.XLOOKUP(B14,Clients!A:A,Clients!B:B,"Not found") -> Overhang Collective | J14: =_xlfn.XLOOKUP(B14,Clients!A:A,Clients!C:C,"Not found") -> Pro
A15: 1014 | B15: 5 | C15: Login | D15: Urgent | E15: Open | F15: 46316.186 | G15: NULL | H15: =IF(E15="Solved",ROUND((G15-F15)*24,1),"") | I15: =_xlfn.XLOOKUP(B15,Clients!A:A,Clients!B:B,"Not found") -> Chalk Up Fontana | J15: =_xlfn.XLOOKUP(B15,Clients!A:A,Clients!C:C,"Not found") -> Growth
A16: 1015 | B16: 5 | C16: Scheduling | D16: Normal | E16: Solved | F16: 46191.603 | G16: 46193.27 | H16: =IF(E16="Solved",ROUND((G16-F16)*24,1),"") -> 40 | I16: =_xlfn.XLOOKUP(B16,Clients!A:A,Clients!B:B,"Not found") -> Chalk Up Fontana | J16: =_xlfn.XLOOKUP(B16,Clients!A:A,Clients!C:C,"Not found") -> Growth
A17: 1016 | B17: 7 | C17: Billing | D17: Normal | E17: Pending | F17: 46314.103 | G17: NULL | H17: =IF(E17="Solved",ROUND((G17-F17)*24,1),"") | I17: =_xlfn.XLOOKUP(B17,Clients!A:A,Clients!B:B,"Not found") -> Dyno Den | J17: =_xlfn.XLOOKUP(B17,Clients!A:A,Clients!C:C,"Not found") -> Starter
A18: 1017 | B18: 8 | C18: SMS Delivery | D18: Normal | E18: Solved | F18: 46241.603 | G18: 46242.103 | H18: =IF(E18="Solved",ROUND((G18-F18)*24,1),"") -> 12 | I18: =_xlfn.XLOOKUP(B18,Clients!A:A,Clients!B:B,"Not found") -> Sloper Station | J18: =_xlfn.XLOOKUP(B18,Clients!A:A,Clients!C:C,"Not found") -> Growth
A19: 1018 | B19: 8 | C19: Login | D19: Low | E19: Solved | F19: 46279.103 | G19: 46279.436 | H19: =IF(E19="Solved",ROUND((G19-F19)*24,1),"") -> 8 | I19: =_xlfn.XLOOKUP(B19,Clients!A:A,Clients!B:B,"Not found") -> Sloper Station | J19: =_xlfn.XLOOKUP(B19,Clients!A:A,Clients!C:C,"Not found") -> Growth
A20: 1019 | B20: 10 | C20: Integration Sync | D20: Normal | E20: Solved | F20: 46224.936 | G20: 46228.936 | H20: =IF(E20="Solved",ROUND((G20-F20)*24,1),"") -> 96 | I20: =_xlfn.XLOOKUP(B20,Clients!A:A,Clients!B:B,"Not found") -> Basecamp Boulders | J20: =_xlfn.XLOOKUP(B20,Clients!A:A,Clients!C:C,"Not found") -> Pro
A21: 1020 | B21: 10 | C21: Email Delivery | D21: High | E21: Open | F21: 46313.603 | G21: NULL | H21: =IF(E21="Solved",ROUND((G21-F21)*24,1),"") | I21: =_xlfn.XLOOKUP(B21,Clients!A:A,Clients!B:B,"Not found") -> Basecamp Boulders | J21: =_xlfn.XLOOKUP(B21,Clients!A:A,Clients!C:C,"Not found") -> Pro
A22: 1021 | B22: 11 | C22: Scheduling | D22: Low | E22: Solved | F22: 46270.77 | G22: 46271.77 | H22: =IF(E22="Solved",ROUND((G22-F22)*24,1),"") -> 24 | I22: =_xlfn.XLOOKUP(B22,Clients!A:A,Clients!B:B,"Not found") -> Jug Haus | J22: =_xlfn.XLOOKUP(B22,Clients!A:A,Clients!C:C,"Not found") -> Growth
A23: 1022 | B23: 12 | C23: Login | D23: Normal | E23: Solved | F23: 46306.186 | G23: 46306.27 | H23: =IF(E23="Solved",ROUND((G23-F23)*24,1),"") -> 2 | I23: =_xlfn.XLOOKUP(B23,Clients!A:A,Clients!B:B,"Not found") -> Topout Climbing | J23: =_xlfn.XLOOKUP(B23,Clients!A:A,Clients!C:C,"Not found") -> Starter
A24: 1023 | B24: 14 | C24: Billing | D24: High | E24: Solved | F24: 46249.936 | G24: 46251.936 | H24: =IF(E24="Solved",ROUND((G24-F24)*24,1),"") -> 48 | I24: =_xlfn.XLOOKUP(B24,Clients!A:A,Clients!B:B,"Not found") -> Flash Point Bouldering | J24: =_xlfn.XLOOKUP(B24,Clients!A:A,Clients!C:C,"Not found") -> Growth
A25: 1024 | B25: 14 | C25: SMS Delivery | D25: Normal | E25: Pending | F25: 46308.27 | G25: NULL | H25: =IF(E25="Solved",ROUND((G25-F25)*24,1),"") | I25: =_xlfn.XLOOKUP(B25,Clients!A:A,Clients!B:B,"Not found") -> Flash Point Bouldering | J25: =_xlfn.XLOOKUP(B25,Clients!A:A,Clients!C:C,"Not found") -> Growth
A26: 1025 | B26: 16 | C26: Billing | D26: Urgent | E26: Solved | F26: 46149.936 | G26: 46150.353 | H26: =IF(E26="Solved",ROUND((G26-F26)*24,1),"") -> 10 | I26: =_xlfn.XLOOKUP(B26,Clients!A:A,Clients!B:B,"Not found") -> Pinch Point Climbing | J26: =_xlfn.XLOOKUP(B26,Clients!A:A,Clients!C:C,"Not found") -> Growth
A27: 1026 | B27: 16 | C27: Integration Sync | D27: High | E27: Solved | F27: 46158.27 | G27: 46160.77 | H27: =IF(E27="Solved",ROUND((G27-F27)*24,1),"") -> 60 | I27: =_xlfn.XLOOKUP(B27,Clients!A:A,Clients!B:B,"Not found") -> Pinch Point Climbing | J27: =_xlfn.XLOOKUP(B27,Clients!A:A,Clients!C:C,"Not found") -> Growth
A28: 1027 | B28: 17 | C28: Scheduling | D28: Low | E28: Open | F28: 46315.103 | G28: NULL | H28: =IF(E28="Solved",ROUND((G28-F28)*24,1),"") | I28: =_xlfn.XLOOKUP(B28,Clients!A:A,Clients!B:B,"Not found") -> Send Shed | J28: =_xlfn.XLOOKUP(B28,Clients!A:A,Clients!C:C,"Not found") -> Starter
A29: 1028 | B29: 18 | C29: Email Delivery | D29: Normal | E29: Solved | F29: 46208.27 | G29: 46209.103 | H29: =IF(E29="Solved",ROUND((G29-F29)*24,1),"") -> 20 | I29: =_xlfn.XLOOKUP(B29,Clients!A:A,Clients!B:B,"Not found") -> Vertical Union | J29: =_xlfn.XLOOKUP(B29,Clients!A:A,Clients!C:C,"Not found") -> Pro
A30: 1029 | B30: 18 | C30: Login | D30: High | E30: Solved | F30: 46287.436 | G30: 46287.561 | H30: =IF(E30="Solved",ROUND((G30-F30)*24,1),"") -> 3 | I30: =_xlfn.XLOOKUP(B30,Clients!A:A,Clients!B:B,"Not found") -> Vertical Union | J30: =_xlfn.XLOOKUP(B30,Clients!A:A,Clients!C:C,"Not found") -> Pro
A31: 1030 | B31: 19 | C31: Integration Sync | D31: Normal | E31: Solved | F31: 46258.27 | G31: 46259.77 | H31: =IF(E31="Solved",ROUND((G31-F31)*24,1),"") -> 36 | I31: =_xlfn.XLOOKUP(B31,Clients!A:A,Clients!B:B,"Not found") -> Mantle Mill | J31: =_xlfn.XLOOKUP(B31,Clients!A:A,Clients!C:C,"Not found") -> Growth
A32: 1031 | B32: 21 | C32: SMS Delivery | D32: Low | E32: Solved | F32: 46229.103 | G32: 46229.77 | H32: =IF(E32="Solved",ROUND((G32-F32)*24,1),"") -> 16 | I32: =_xlfn.XLOOKUP(B32,Clients!A:A,Clients!B:B,"Not found") -> Campus Board Co | J32: =_xlfn.XLOOKUP(B32,Clients!A:A,Clients!C:C,"Not found") -> Growth
A33: 1032 | B33: 22 | C33: Billing | D33: Normal | E33: Solved | F33: 46262.436 | G33: 46263.686 | H33: =IF(E33="Solved",ROUND((G33-F33)*24,1),"") -> 30 | I33: =_xlfn.XLOOKUP(B33,Clients!A:A,Clients!B:B,"Not found") -> Gneiss Climbing | J33: =_xlfn.XLOOKUP(B33,Clients!A:A,Clients!C:C,"Not found") -> Pro
A34: 1033 | B34: 22 | C34: Scheduling | D34: Normal | E34: Open | F34: 46311.603 | G34: NULL | H34: =IF(E34="Solved",ROUND((G34-F34)*24,1),"") | I34: =_xlfn.XLOOKUP(B34,Clients!A:A,Clients!B:B,"Not found") -> Gneiss Climbing | J34: =_xlfn.XLOOKUP(B34,Clients!A:A,Clients!C:C,"Not found") -> Pro
A35: 1034 | B35: 23 | C35: Login | D35: Low | E35: Solved | F35: 46283.27 | G35: 46283.478 | H35: =IF(E35="Solved",ROUND((G35-F35)*24,1),"") -> 5 | I35: =_xlfn.XLOOKUP(B35,Clients!A:A,Clients!B:B,"Not found") -> Smear Club | J35: =_xlfn.XLOOKUP(B35,Clients!A:A,Clients!C:C,"Not found") -> Starter
A36: 1035 | B36: 24 | C36: Email Delivery | D36: High | E36: Solved | F36: 46274.936 | G36: 46275.52 | H36: =IF(E36="Solved",ROUND((G36-F36)*24,1),"") -> 14 | I36: =_xlfn.XLOOKUP(B36,Clients!A:A,Clients!B:B,"Not found") -> Rope Gun Climbing | J36: =_xlfn.XLOOKUP(B36,Clients!A:A,Clients!C:C,"Not found") -> Growth
A37: 1036 | B37: 26 | C37: Integration Sync | D37: Urgent | E37: Solved | F37: 46289.52 | G37: 46289.895 | H37: =IF(E37="Solved",ROUND((G37-F37)*24,1),"") -> 9 | I37: =_xlfn.XLOOKUP(B37,Clients!A:A,Clients!B:B,"Not found") -> Kneebar Bouldering | J37: =_xlfn.XLOOKUP(B37,Clients!A:A,Clients!C:C,"Not found") -> Growth
A38: 1037 | B38: 26 | C38: SMS Delivery | D38: Normal | E38: Open | F38: 46313.27 | G38: NULL | H38: =IF(E38="Solved",ROUND((G38-F38)*24,1),"") | I38: =_xlfn.XLOOKUP(B38,Clients!A:A,Clients!B:B,"Not found") -> Kneebar Bouldering | J38: =_xlfn.XLOOKUP(B38,Clients!A:A,Clients!C:C,"Not found") -> Growth
A39: 1038 | B39: 28 | C39: Scheduling | D39: Low | E39: Solved | F39: 46170.77 | G39: 46174.52 | H39: =IF(E39="Solved",ROUND((G39-F39)*24,1),"") -> 90 | I39: =_xlfn.XLOOKUP(B39,Clients!A:A,Clients!B:B,"Not found") -> Peak Pursuit Climbing | J39: =_xlfn.XLOOKUP(B39,Clients!A:A,Clients!C:C,"Not found") -> Pro
A40: 1039 | B40: 28 | C40: Billing | D40: Normal | E40: Solved | F40: 46216.603 | G40: 46217.686 | H40: =IF(E40="Solved",ROUND((G40-F40)*24,1),"") -> 26 | I40: =_xlfn.XLOOKUP(B40,Clients!A:A,Clients!B:B,"Not found") -> Peak Pursuit Climbing | J40: =_xlfn.XLOOKUP(B40,Clients!A:A,Clients!C:C,"Not found") -> Pro
...

Sheet Clients
A1: client_id | B1: name | C1: plan_tier | D1: signup_date | E1: status
A2: 1 | B2: Summit Bouldering | C2: Pro | D2: 45336 | E2: Active
A3: 2 | B3: Granite Hall Climbing | C3: Growth | D3: 45415 | E3: Active
A4: 3 | B4: Crimp City Gym | C4: Starter | D4: 45677 | E4: Active
A5: 4 | B5: Overhang Collective | C5: Pro | D5: 45238 | E5: Active
A6: 5 | B6: Chalk Up Fontana | C6: Growth | D6: 45823 | E6: Active
A7: 6 | B7: Redpoint Climbing Center | C7: Pro | D7: 45526 | E7: Active
A8: 7 | B8: Dyno Den | C8: Starter | D8: 46266 | E8: Trial
A9: 8 | B9: Sloper Station | C9: Growth | D9: 45628 | E9: Active
A10: 9 | B10: The Arete Gym | C10: Starter | D10: 45727 | E10: Churned
A11: 10 | B11: Basecamp Boulders | C11: Pro | D11: 45199 | E11: Active
A12: 11 | B12: Jug Haus | C12: Growth | D12: 45845 | E12: Active
A13: 12 | B13: Topout Climbing | C13: Starter | D13: 46253 | E13: Trial
... A30: 29 | B30: Bolt Line Bouldering | C30: Growth | D30: 45912 | E30: Active
